[2025-05-18 13:13:06 +0900] [9746] [DEBUG] Current configuration:
  config: ./gunicorn.conf.py
  wsgi_app: None
  bind: ['0.0.0.0:8000']
  backlog: 2048
  workers: 4
  worker_class: sync
  threads: 1
  worker_connections: 1000
  max_requests: 0
  max_requests_jitter: 0
  timeout: 30
  graceful_timeout: 30
  keepalive: 2
  limit_request_line: 4094
  limit_request_fields: 100
  limit_request_field_size: 8190
  reload: False
  reload_engine: auto
  reload_extra_files: []
  spew: False
  check_config: False
  print_config: False
  preload_app: False
  sendfile: None
  reuse_port: False
  chdir: /Users/minghui/Desktop/deathbill_911
  daemon: False
  raw_env: []
  pidfile: None
  worker_tmp_dir: None
  user: 501
  group: 20
  umask: 0
  initgroups: False
  tmp_upload_dir: None
  secure_scheme_headers: {'X-FORWARDED-PROTOCOL': 'ssl', 'X-FORWARDED-PROTO': 'https', 'X-FORWARDED-SSL': 'on'}
  forwarded_allow_ips: ['127.0.0.1']
  accesslog: None
  disable_redirect_access_to_syslog: False
  access_log_format: %(h)s %(l)s %(u)s %(t)s "%(r)s" %(s)s %(b)s "%(f)s" "%(a)s"
  errorlog: gunicorn.log
  loglevel: debug
  capture_output: False
  logger_class: gunicorn.glogging.Logger
  logconfig: None
  logconfig_dict: {}
  logconfig_json: None
  syslog_addr: unix:///var/run/syslog
  syslog: False
  syslog_prefix: None
  syslog_facility: user
  enable_stdio_inheritance: False
  statsd_host: None
  dogstatsd_tags: 
  statsd_prefix: 
  proc_name: None
  default_proc_name: app:app
  pythonpath: None
  paste: None
  on_starting: <function OnStarting.on_starting at 0x10ffd3560>
  on_reload: <function OnReload.on_reload at 0x10ffd36a0>
  when_ready: <function WhenReady.when_ready at 0x10ffd37e0>
  pre_fork: <function Prefork.pre_fork at 0x10ffd39c0>
  post_fork: <function Postfork.post_fork at 0x10ffd3b00>
  post_worker_init: <function PostWorkerInit.post_worker_init at 0x10ffd3c40>
  worker_int: <function WorkerInt.worker_int at 0x10ffd3d80>
  worker_abort: <function WorkerAbort.worker_abort at 0x10ffd3ec0>
  pre_exec: <function PreExec.pre_exec at 0x110010040>
  pre_request: <function PreRequest.pre_request at 0x110010180>
  post_request: <function PostRequest.post_request at 0x110010220>
  child_exit: <function ChildExit.child_exit at 0x110010360>
  worker_exit: <function WorkerExit.worker_exit at 0x1100104a0>
  nworkers_changed: <function NumWorkersChanged.nworkers_changed at 0x1100105e0>
  on_exit: <function OnExit.on_exit at 0x110010720>
  ssl_context: <function NewSSLContext.ssl_context at 0x110010900>
  proxy_protocol: False
  proxy_allow_ips: ['127.0.0.1']
  keyfile: None
  certfile: None
  ssl_version: 2
  cert_reqs: 0
  ca_certs: None
  suppress_ragged_eofs: True
  do_handshake_on_connect: False
  ciphers: None
  raw_paste_global_conf: []
  strip_header_spaces: False
  permit_unconventional_http_method: False
  permit_unconventional_http_version: False
  casefold_http_method: False
  header_map: drop
  tolerate_dangerous_framing: False
[2025-05-18 13:13:06 +0900] [9746] [INFO] Starting gunicorn 22.0.0
[2025-05-18 13:13:06 +0900] [9746] [DEBUG] Arbiter booted
[2025-05-18 13:13:06 +0900] [9746] [INFO] Listening at: http://0.0.0.0:8000 (9746)
[2025-05-18 13:13:06 +0900] [9746] [INFO] Using worker: sync
[2025-05-18 13:13:06 +0900] [9747] [INFO] Booting worker with pid: 9747
[2025-05-18 13:13:06 +0900] [9748] [INFO] Booting worker with pid: 9748
[2025-05-18 13:13:06 +0900] [9749] [INFO] Booting worker with pid: 9749
[2025-05-18 13:13:06 +0900] [9750] [INFO] Booting worker with pid: 9750
[2025-05-18 13:13:06 +0900] [9746] [DEBUG] 4 workers
[2025-05-18 13:13:07 +0900] [9748] [ERROR] Exception in worker process
Traceback (most recent call last):
  File "/Users/minghui/Desktop/deathbill_911/venv/lib/python3.13/site-packages/gunicorn/arbiter.py", line 609, in spawn_worker
    worker.init_process()
    ~~~~~~~~~~~~~~~~~~~^^
  File "/Users/minghui/Desktop/deathbill_911/venv/lib/python3.13/site-packages/gunicorn/workers/base.py", line 134, in init_process
    self.load_wsgi()
    ~~~~~~~~~~~~~~^^
  File "/Users/minghui/Desktop/deathbill_911/venv/lib/python3.13/site-packages/gunicorn/workers/base.py", line 146, in load_wsgi
    self.wsgi = self.app.wsgi()
                ~~~~~~~~~~~~~^^
  File "/Users/minghui/Desktop/deathbill_911/venv/lib/python3.13/site-packages/gunicorn/app/base.py", line 67, in wsgi
    self.callable = self.load()
                    ~~~~~~~~~^^
  File "/Users/minghui/Desktop/deathbill_911/venv/lib/python3.13/site-packages/gunicorn/app/wsgiapp.py", line 58, in load
    return self.load_wsgiapp()
           ~~~~~~~~~~~~~~~~~^^
  File "/Users/minghui/Desktop/deathbill_911/venv/lib/python3.13/site-packages/gunicorn/app/wsgiapp.py", line 48, in load_wsgiapp
    return util.import_app(self.app_uri)
           ~~~~~~~~~~~~~~~^^^^^^^^^^^^^^
  File "/Users/minghui/Desktop/deathbill_911/venv/lib/python3.13/site-packages/gunicorn/util.py", line 371, in import_app
    mod = importlib.import_module(module)
  File "/Library/Frameworks/Python.framework/Versions/3.13/lib/python3.13/importlib/__init__.py", line 88, in import_module
    return _bootstrap._gcd_import(name[level:], package, level)
           ~~~~~~~~~~~~~~~~~~~~~~^^^^^^^^^^^^^^^^^^^^^^^^^^^^^^
  File "<frozen importlib._bootstrap>", line 1387, in _gcd_import
  File "<frozen importlib._bootstrap>", line 1360, in _find_and_load
  File "<frozen importlib._bootstrap>", line 1331, in _find_and_load_unlocked
  File "<frozen importlib._bootstrap>", line 935, in _load_unlocked
  File "<frozen importlib._bootstrap_external>", line 1026, in exec_module
  File "<frozen importlib._bootstrap>", line 488, in _call_with_frames_removed
  File "/Users/minghui/Desktop/deathbill_911/app.py", line 10, in <module>
    from retrying import retry
ModuleNotFoundError: No module named 'retrying'
[2025-05-18 13:13:07 +0900] [9748] [INFO] Worker exiting (pid: 9748)
[2025-05-18 13:13:07 +0900] [9747] [ERROR] Exception in worker process
Traceback (most recent call last):
  File "/Users/minghui/Desktop/deathbill_911/venv/lib/python3.13/site-packages/gunicorn/arbiter.py", line 609, in spawn_worker
    worker.init_process()
    ~~~~~~~~~~~~~~~~~~~^^
  File "/Users/minghui/Desktop/deathbill_911/venv/lib/python3.13/site-packages/gunicorn/workers/base.py", line 134, in init_process
    self.load_wsgi()
    ~~~~~~~~~~~~~~^^
  File "/Users/minghui/Desktop/deathbill_911/venv/lib/python3.13/site-packages/gunicorn/workers/base.py", line 146, in load_wsgi
    self.wsgi = self.app.wsgi()
                ~~~~~~~~~~~~~^^
  File "/Users/minghui/Desktop/deathbill_911/venv/lib/python3.13/site-packages/gunicorn/app/base.py", line 67, in wsgi
    self.callable = self.load()
                    ~~~~~~~~~^^
  File "/Users/minghui/Desktop/deathbill_911/venv/lib/python3.13/site-packages/gunicorn/app/wsgiapp.py", line 58, in load
    return self.load_wsgiapp()
           ~~~~~~~~~~~~~~~~~^^
  File "/Users/minghui/Desktop/deathbill_911/venv/lib/python3.13/site-packages/gunicorn/app/wsgiapp.py", line 48, in load_wsgiapp
    return util.import_app(self.app_uri)
           ~~~~~~~~~~~~~~~^^^^^^^^^^^^^^
  File "/Users/minghui/Desktop/deathbill_911/venv/lib/python3.13/site-packages/gunicorn/util.py", line 371, in import_app
    mod = importlib.import_module(module)
  File "/Library/Frameworks/Python.framework/Versions/3.13/lib/python3.13/importlib/__init__.py", line 88, in import_module
    return _bootstrap._gcd_import(name[level:], package, level)
           ~~~~~~~~~~~~~~~~~~~~~~^^^^^^^^^^^^^^^^^^^^^^^^^^^^^^
  File "<frozen importlib._bootstrap>", line 1387, in _gcd_import
  File "<frozen importlib._bootstrap>", line 1360, in _find_and_load
  File "<frozen importlib._bootstrap>", line 1331, in _find_and_load_unlocked
  File "<frozen importlib._bootstrap>", line 935, in _load_unlocked
  File "<frozen importlib._bootstrap_external>", line 1026, in exec_module
  File "<frozen importlib._bootstrap>", line 488, in _call_with_frames_removed
  File "/Users/minghui/Desktop/deathbill_911/app.py", line 10, in <module>
    from retrying import retry
ModuleNotFoundError: No module named 'retrying'
[2025-05-18 13:13:07 +0900] [9747] [INFO] Worker exiting (pid: 9747)
[2025-05-18 13:13:07 +0900] [9749] [ERROR] Exception in worker process
Traceback (most recent call last):
  File "/Users/minghui/Desktop/deathbill_911/venv/lib/python3.13/site-packages/gunicorn/arbiter.py", line 609, in spawn_worker
    worker.init_process()
    ~~~~~~~~~~~~~~~~~~~^^
  File "/Users/minghui/Desktop/deathbill_911/venv/lib/python3.13/site-packages/gunicorn/workers/base.py", line 134, in init_process
    self.load_wsgi()
    ~~~~~~~~~~~~~~^^
  File "/Users/minghui/Desktop/deathbill_911/venv/lib/python3.13/site-packages/gunicorn/workers/base.py", line 146, in load_wsgi
    self.wsgi = self.app.wsgi()
                ~~~~~~~~~~~~~^^
  File "/Users/minghui/Desktop/deathbill_911/venv/lib/python3.13/site-packages/gunicorn/app/base.py", line 67, in wsgi
    self.callable = self.load()
                    ~~~~~~~~~^^
  File "/Users/minghui/Desktop/deathbill_911/venv/lib/python3.13/site-packages/gunicorn/app/wsgiapp.py", line 58, in load
    return self.load_wsgiapp()
           ~~~~~~~~~~~~~~~~~^^
  File "/Users/minghui/Desktop/deathbill_911/venv/lib/python3.13/site-packages/gunicorn/app/wsgiapp.py", line 48, in load_wsgiapp
    return util.import_app(self.app_uri)
           ~~~~~~~~~~~~~~~^^^^^^^^^^^^^^
  File "/Users/minghui/Desktop/deathbill_911/venv/lib/python3.13/site-packages/gunicorn/util.py", line 371, in import_app
    mod = importlib.import_module(module)
  File "/Library/Frameworks/Python.framework/Versions/3.13/lib/python3.13/importlib/__init__.py", line 88, in import_module
    return _bootstrap._gcd_import(name[level:], package, level)
           ~~~~~~~~~~~~~~~~~~~~~~^^^^^^^^^^^^^^^^^^^^^^^^^^^^^^
  File "<frozen importlib._bootstrap>", line 1387, in _gcd_import
  File "<frozen importlib._bootstrap>", line 1360, in _find_and_load
  File "<frozen importlib._bootstrap>", line 1331, in _find_and_load_unlocked
  File "<frozen importlib._bootstrap>", line 935, in _load_unlocked
  File "<frozen importlib._bootstrap_external>", line 1026, in exec_module
  File "<frozen importlib._bootstrap>", line 488, in _call_with_frames_removed
  File "/Users/minghui/Desktop/deathbill_911/app.py", line 10, in <module>
    from retrying import retry
ModuleNotFoundError: No module named 'retrying'
[2025-05-18 13:13:07 +0900] [9749] [INFO] Worker exiting (pid: 9749)
[2025-05-18 13:13:07 +0900] [9750] [ERROR] Exception in worker process
Traceback (most recent call last):
  File "/Users/minghui/Desktop/deathbill_911/venv/lib/python3.13/site-packages/gunicorn/arbiter.py", line 609, in spawn_worker
    worker.init_process()
    ~~~~~~~~~~~~~~~~~~~^^
  File "/Users/minghui/Desktop/deathbill_911/venv/lib/python3.13/site-packages/gunicorn/workers/base.py", line 134, in init_process
    self.load_wsgi()
    ~~~~~~~~~~~~~~^^
  File "/Users/minghui/Desktop/deathbill_911/venv/lib/python3.13/site-packages/gunicorn/workers/base.py", line 146, in load_wsgi
    self.wsgi = self.app.wsgi()
                ~~~~~~~~~~~~~^^
  File "/Users/minghui/Desktop/deathbill_911/venv/lib/python3.13/site-packages/gunicorn/app/base.py", line 67, in wsgi
    self.callable = self.load()
                    ~~~~~~~~~^^
  File "/Users/minghui/Desktop/deathbill_911/venv/lib/python3.13/site-packages/gunicorn/app/wsgiapp.py", line 58, in load
    return self.load_wsgiapp()
           ~~~~~~~~~~~~~~~~~^^
  File "/Users/minghui/Desktop/deathbill_911/venv/lib/python3.13/site-packages/gunicorn/app/wsgiapp.py", line 48, in load_wsgiapp
    return util.import_app(self.app_uri)
           ~~~~~~~~~~~~~~~^^^^^^^^^^^^^^
  File "/Users/minghui/Desktop/deathbill_911/venv/lib/python3.13/site-packages/gunicorn/util.py", line 371, in import_app
    mod = importlib.import_module(module)
  File "/Library/Frameworks/Python.framework/Versions/3.13/lib/python3.13/importlib/__init__.py", line 88, in import_module
    return _bootstrap._gcd_import(name[level:], package, level)
           ~~~~~~~~~~~~~~~~~~~~~~^^^^^^^^^^^^^^^^^^^^^^^^^^^^^^
  File "<frozen importlib._bootstrap>", line 1387, in _gcd_import
  File "<frozen importlib._bootstrap>", line 1360, in _find_and_load
  File "<frozen importlib._bootstrap>", line 1331, in _find_and_load_unlocked
  File "<frozen importlib._bootstrap>", line 935, in _load_unlocked
  File "<frozen importlib._bootstrap_external>", line 1026, in exec_module
  File "<frozen importlib._bootstrap>", line 488, in _call_with_frames_removed
  File "/Users/minghui/Desktop/deathbill_911/app.py", line 10, in <module>
    from retrying import retry
ModuleNotFoundError: No module named 'retrying'
[2025-05-18 13:13:07 +0900] [9750] [INFO] Worker exiting (pid: 9750)
[2025-05-18 13:13:07 +0900] [9746] [ERROR] Worker (pid:9750) exited with code 3
[2025-05-18 13:13:07 +0900] [9746] [ERROR] Worker (pid:9749) was sent SIGTERM!
[2025-05-18 13:13:07 +0900] [9746] [ERROR] Worker (pid:9748) exited with code 3
[2025-05-18 17:38:25 +0900] [10684] [DEBUG] Current configuration:
  config: ./gunicorn.conf.py
  wsgi_app: None
  bind: ['0.0.0.0:8000']
  backlog: 2048
  workers: 4
  worker_class: sync
  threads: 1
  worker_connections: 1000
  max_requests: 0
  max_requests_jitter: 0
  timeout: 30
  graceful_timeout: 30
  keepalive: 2
  limit_request_line: 4094
  limit_request_fields: 100
  limit_request_field_size: 8190
  reload: False
  reload_engine: auto
  reload_extra_files: []
  spew: False
  check_config: False
  print_config: False
  preload_app: False
  sendfile: None
  reuse_port: False
  chdir: /Users/minghui/Desktop/deathbill_911
  daemon: False
  raw_env: []
  pidfile: None
  worker_tmp_dir: None
  user: 501
  group: 20
  umask: 0
  initgroups: False
  tmp_upload_dir: None
  secure_scheme_headers: {'X-FORWARDED-PROTOCOL': 'ssl', 'X-FORWARDED-PROTO': 'https', 'X-FORWARDED-SSL': 'on'}
  forwarded_allow_ips: ['127.0.0.1', '::1']
  accesslog: None
  disable_redirect_access_to_syslog: False
  access_log_format: %(h)s %(l)s %(u)s %(t)s "%(r)s" %(s)s %(b)s "%(f)s" "%(a)s"
  errorlog: gunicorn.log
  loglevel: debug
  capture_output: False
  logger_class: gunicorn.glogging.Logger
  logconfig: None
  logconfig_dict: {}
  logconfig_json: None
  syslog_addr: unix:///var/run/syslog
  syslog: False
  syslog_prefix: None
  syslog_facility: user
  enable_stdio_inheritance: False
  statsd_host: None
  dogstatsd_tags: 
  statsd_prefix: 
  proc_name: None
  default_proc_name: app:app
  pythonpath: None
  paste: None
  on_starting: <function OnStarting.on_starting at 0x10956f4c0>
  on_reload: <function OnReload.on_reload at 0x10956f600>
  when_ready: <function WhenReady.when_ready at 0x10956f740>
  pre_fork: <function Prefork.pre_fork at 0x10956f920>
  post_fork: <function Postfork.post_fork at 0x10956fa60>
  post_worker_init: <function PostWorkerInit.post_worker_init at 0x10956fba0>
  worker_int: <function WorkerInt.worker_int at 0x10956fce0>
  worker_abort: <function WorkerAbort.worker_abort at 0x10956fe20>
  pre_exec: <function PreExec.pre_exec at 0x10956ff60>
  pre_request: <function PreRequest.pre_request at 0x1095900e0>
  post_request: <function PostRequest.post_request at 0x109590180>
  child_exit: <function ChildExit.child_exit at 0x1095902c0>
  worker_exit: <function WorkerExit.worker_exit at 0x109590400>
  nworkers_changed: <function NumWorkersChanged.nworkers_changed at 0x109590540>
  on_exit: <function OnExit.on_exit at 0x109590680>
  ssl_context: <function NewSSLContext.ssl_context at 0x109590860>
  proxy_protocol: False
  proxy_allow_ips: ['127.0.0.1', '::1']
  keyfile: None
  certfile: None
  ssl_version: 2
  cert_reqs: 0
  ca_certs: None
  suppress_ragged_eofs: True
  do_handshake_on_connect: False
  ciphers: None
  raw_paste_global_conf: []
  permit_obsolete_folding: False
  strip_header_spaces: False
  permit_unconventional_http_method: False
  permit_unconventional_http_version: False
  casefold_http_method: False
  forwarder_headers: ['SCRIPT_NAME', 'PATH_INFO']
  header_map: drop
[2025-05-18 17:38:25 +0900] [10684] [INFO] Starting gunicorn 23.0.0
[2025-05-18 17:38:25 +0900] [10684] [ERROR] Connection in use: ('0.0.0.0', 8000)
[2025-05-18 17:38:25 +0900] [10684] [ERROR] connection to ('0.0.0.0', 8000) failed: [Errno 48] Address already in use
[2025-05-18 17:38:25 +0900] [10684] [DEBUG] Retrying in 1 second.
[2025-05-18 17:38:26 +0900] [10684] [ERROR] Connection in use: ('0.0.0.0', 8000)
[2025-05-18 17:38:26 +0900] [10684] [ERROR] connection to ('0.0.0.0', 8000) failed: [Errno 48] Address already in use
[2025-05-18 17:38:26 +0900] [10684] [DEBUG] Retrying in 1 second.
[2025-05-18 17:38:27 +0900] [10684] [ERROR] Connection in use: ('0.0.0.0', 8000)
[2025-05-18 17:38:27 +0900] [10684] [ERROR] connection to ('0.0.0.0', 8000) failed: [Errno 48] Address already in use
[2025-05-18 17:38:27 +0900] [10684] [DEBUG] Retrying in 1 second.
[2025-05-18 17:38:28 +0900] [10684] [ERROR] Connection in use: ('0.0.0.0', 8000)
[2025-05-18 17:38:28 +0900] [10684] [ERROR] connection to ('0.0.0.0', 8000) failed: [Errno 48] Address already in use
[2025-05-18 17:38:28 +0900] [10684] [DEBUG] Retrying in 1 second.
[2025-05-18 17:38:29 +0900] [10684] [ERROR] Connection in use: ('0.0.0.0', 8000)
[2025-05-18 17:38:29 +0900] [10684] [ERROR] connection to ('0.0.0.0', 8000) failed: [Errno 48] Address already in use
[2025-05-18 17:38:29 +0900] [10684] [DEBUG] Retrying in 1 second.
[2025-05-18 17:38:30 +0900] [10684] [ERROR] Can't connect to ('0.0.0.0', 8000)
[2025-05-28 01:27:57 +0900] [8828] [INFO] Starting gunicorn 23.0.0
[2025-05-28 01:27:57 +0900] [8828] [INFO] Listening at: http://0.0.0.0:8000 (8828)
[2025-05-28 01:27:57 +0900] [8828] [INFO] Using worker: sync
[2025-05-28 01:27:57 +0900] [8829] [INFO] Booting worker with pid: 8829
[2025-05-28 02:22:19 +0900] [8828] [INFO] Handling signal: term
[2025-05-28 02:22:19 +0900] [8829] [INFO] Worker exiting (pid: 8829)
[2025-05-28 02:22:20 +0900] [8828] [INFO] Shutting down: Master
